2022-03-05 10:24:32,589 -  nornir.core -     INFO -        run() - Running task 'update_intfs_task' with args {} on 1 hosts
2022-03-05 10:24:32,637 - nornir.core.task -    ERROR -      start() - Host '10.245.29.4': task 'update_intfs_task' failed with traceback:
Traceback (most recent call last):
  File "D:\Python\Django_Project\VirEnv\lib\site-packages\nornir\core\task.py", line 99, in start
    r = self.task(self, **self.params)
  File "D:\Python\Django_Project\Scripts\nornir_intf_getter.py", line 17, in update_intfs_task
    device_obj = Device.objects.get(ip=task.host.hostname)
  File "D:\Python\Django_Project\VirEnv\lib\site-packages\django\db\models\manager.py", line 85, in manager_method
    return getattr(self.get_queryset(), name)(*args, **kwargs)
  File "D:\Python\Django_Project\VirEnv\lib\site-packages\django\db\models\query.py", line 428, in get
    clone = self._chain() if self.query.combinator else self.filter(*args, **kwargs)
  File "D:\Python\Django_Project\VirEnv\lib\site-packages\django\db\models\query.py", line 974, in filter
    return self._filter_or_exclude(False, args, kwargs)
  File "D:\Python\Django_Project\VirEnv\lib\site-packages\django\db\models\query.py", line 992, in _filter_or_exclude
    clone._filter_or_exclude_inplace(negate, args, kwargs)
  File "D:\Python\Django_Project\VirEnv\lib\site-packages\django\db\models\query.py", line 999, in _filter_or_exclude_inplace
    self._query.add_q(Q(*args, **kwargs))
  File "D:\Python\Django_Project\VirEnv\lib\site-packages\django\db\models\sql\query.py", line 1375, in add_q
    clause, _ = self._add_q(q_object, self.used_aliases)
  File "D:\Python\Django_Project\VirEnv\lib\site-packages\django\db\models\sql\query.py", line 1396, in _add_q
    child_clause, needed_inner = self.build_filter(
  File "D:\Python\Django_Project\VirEnv\lib\site-packages\django\db\models\sql\query.py", line 1271, in build_filter
    lookups, parts, reffed_expression = self.solve_lookup_type(arg)
  File "D:\Python\Django_Project\VirEnv\lib\site-packages\django\db\models\sql\query.py", line 1099, in solve_lookup_type
    _, field, _, lookup_parts = self.names_to_path(lookup_splitted, self.get_meta())
  File "D:\Python\Django_Project\VirEnv\lib\site-packages\django\db\models\sql\query.py", line 1522, in names_to_path
    raise FieldError("Cannot resolve keyword '%s' into field. "
django.core.exceptions.FieldError: Cannot resolve keyword 'ip' into field. Choices are: enable_password, hostname, id, interface, ip_address, password, ssh_port, type, username, vendor

2022-03-05 10:25:38,580 -  nornir.core -     INFO -        run() - Running task 'update_intfs_task' with args {} on 1 hosts
2022-03-05 10:27:12,554 -  nornir.core -     INFO -        run() - Running task 'update_intfs_task' with args {} on 1 hosts
2022-03-05 11:01:18,821 -  nornir.core -     INFO -        run() - Running task 'update_intfs_task' with args {} on 2 hosts
2022-03-05 11:02:47,095 -  nornir.core -     INFO -        run() - Running task 'update_intfs_task' with args {} on 2 hosts
2022-03-05 11:04:15,160 -  nornir.core -     INFO -        run() - Running task 'update_intfs_task' with args {} on 2 hosts
2022-03-05 11:04:47,122 -  nornir.core -     INFO -        run() - Running task 'update_intfs_task' with args {} on 2 hosts
2022-03-05 11:07:51,676 -  nornir.core -     INFO -        run() - Running task 'update_intfs_task' with args {} on 2 hosts
2022-03-05 11:08:52,326 -  nornir.core -     INFO -        run() - Running task 'update_intfs_task' with args {} on 2 hosts
2022-03-05 11:10:04,056 -  nornir.core -     INFO -        run() - Running task 'update_intfs_task' with args {} on 2 hosts
2022-03-05 11:11:44,270 -  nornir.core -     INFO -        run() - Running task 'update_intfs_task' with args {} on 2 hosts
